[2, 6047, 11716, 603, 476, 4765, 3679, 17355, 235265, 1165, 22346, 577, 2115, 578, 3280, 18225, 17273, 591, 11716, 235275, 575, 5742, 674, 9065, 26696, 685, 476, 3733, 235265]
<bos>OpenAI is a private research laboratory. It aims to develop and direct artificial intelligence (AI) in ways that benefit humanity as a whole.
['<bos>', 'Open', 'AI', '▁is', '▁a', '▁private', '▁research', '▁laboratory', '.', '▁It', '▁aims', '▁to', '▁develop', '▁and', '▁direct', '▁artificial', '▁intelligence', '▁(', 'AI', ')', '▁in', '▁ways', '▁that', '▁benefit', '▁humanity', '▁as', '▁a', '▁whole', '.']
Traceback (most recent call last):
  File "/home/ych22001/miniconda3/envs/unsloth_env/lib/python3.10/site-packages/huggingface_hub/utils/_errors.py", line 304, in hf_raise_for_status
    response.raise_for_status()
  File "/home/ych22001/miniconda3/envs/unsloth_env/lib/python3.10/site-packages/requests/models.py", line 1024, in raise_for_status
    raise HTTPError(http_error_msg, response=self)
requests.exceptions.HTTPError: 401 Client Error: Unauthorized for url: https://huggingface.co/google/gemma-2-9b/resolve/main/config.json

The above exception was the direct cause of the following exception:

Traceback (most recent call last):
  File "/home/ych22001/miniconda3/envs/unsloth_env/lib/python3.10/site-packages/transformers/utils/hub.py", line 402, in cached_file
    resolved_file = hf_hub_download(
  File "/home/ych22001/miniconda3/envs/unsloth_env/lib/python3.10/site-packages/huggingface_hub/utils/_validators.py", line 114, in _inner_fn
    return fn(*args, **kwargs)
  File "/home/ych22001/miniconda3/envs/unsloth_env/lib/python3.10/site-packages/huggingface_hub/file_download.py", line 1221, in hf_hub_download
    return _hf_hub_download_to_cache_dir(
  File "/home/ych22001/miniconda3/envs/unsloth_env/lib/python3.10/site-packages/huggingface_hub/file_download.py", line 1325, in _hf_hub_download_to_cache_dir
    _raise_on_head_call_error(head_call_error, force_download, local_files_only)
  File "/home/ych22001/miniconda3/envs/unsloth_env/lib/python3.10/site-packages/huggingface_hub/file_download.py", line 1823, in _raise_on_head_call_error
    raise head_call_error
  File "/home/ych22001/miniconda3/envs/unsloth_env/lib/python3.10/site-packages/huggingface_hub/file_download.py", line 1722, in _get_metadata_or_catch_error
    metadata = get_hf_file_metadata(url=url, proxies=proxies, timeout=etag_timeout, headers=headers)
  File "/home/ych22001/miniconda3/envs/unsloth_env/lib/python3.10/site-packages/huggingface_hub/utils/_validators.py", line 114, in _inner_fn
    return fn(*args, **kwargs)
  File "/home/ych22001/miniconda3/envs/unsloth_env/lib/python3.10/site-packages/huggingface_hub/file_download.py", line 1645, in get_hf_file_metadata
    r = _request_wrapper(
  File "/home/ych22001/miniconda3/envs/unsloth_env/lib/python3.10/site-packages/huggingface_hub/file_download.py", line 372, in _request_wrapper
    response = _request_wrapper(
  File "/home/ych22001/miniconda3/envs/unsloth_env/lib/python3.10/site-packages/huggingface_hub/file_download.py", line 396, in _request_wrapper
    hf_raise_for_status(response)
  File "/home/ych22001/miniconda3/envs/unsloth_env/lib/python3.10/site-packages/huggingface_hub/utils/_errors.py", line 321, in hf_raise_for_status
    raise GatedRepoError(message, response) from e
huggingface_hub.utils._errors.GatedRepoError: 401 Client Error. (Request ID: Root=1-669939ad-13b5e64a44bc243d38718486;1343a533-578c-45d4-bb64-f0511d4db13e)

Cannot access gated repo for url https://huggingface.co/google/gemma-2-9b/resolve/main/config.json.
Access to model google/gemma-2-9b is restricted. You must be authenticated to access it.

The above exception was the direct cause of the following exception:

Traceback (most recent call last):
  File "/home/ych22001/LLM/LLM_ALFWorld/ALFWorld_test/Count_show_tokens_all_tasks.py", line 49, in <module>
    tokenizer = AutoTokenizer.from_pretrained(m)
  File "/home/ych22001/miniconda3/envs/unsloth_env/lib/python3.10/site-packages/transformers/models/auto/tokenization_auto.py", line 846, in from_pretrained
    config = AutoConfig.from_pretrained(
  File "/home/ych22001/miniconda3/envs/unsloth_env/lib/python3.10/site-packages/transformers/models/auto/configuration_auto.py", line 966, in from_pretrained
    config_dict, unused_kwargs = PretrainedConfig.get_config_dict(pretrained_model_name_or_path, **kwargs)
  File "/home/ych22001/miniconda3/envs/unsloth_env/lib/python3.10/site-packages/transformers/configuration_utils.py", line 632, in get_config_dict
    config_dict, kwargs = cls._get_config_dict(pretrained_model_name_or_path, **kwargs)
  File "/home/ych22001/miniconda3/envs/unsloth_env/lib/python3.10/site-packages/transformers/configuration_utils.py", line 689, in _get_config_dict
    resolved_config_file = cached_file(
  File "/home/ych22001/miniconda3/envs/unsloth_env/lib/python3.10/site-packages/transformers/utils/hub.py", line 420, in cached_file
    raise EnvironmentError(
OSError: You are trying to access a gated repo.
Make sure to have access to it at https://huggingface.co/google/gemma-2-9b.
401 Client Error. (Request ID: Root=1-669939ad-13b5e64a44bc243d38718486;1343a533-578c-45d4-bb64-f0511d4db13e)

Cannot access gated repo for url https://huggingface.co/google/gemma-2-9b/resolve/main/config.json.
Access to model google/gemma-2-9b is restricted. You must be authenticated to access it.
